{
 "cells": [
  {
   "cell_type": "markdown",
   "id": "5dfcd111",
   "metadata": {},
   "source": [
    "# Metadata\n",
    "\n",
    "**Python Topics** - debugging_and_tracing\n",
    "\n",
    "**Type** - query\n",
    "\n",
    "**Target Number of Turns (User + Assistant)** - 3\n"
   ]
  },
  {
   "cell_type": "markdown",
   "id": "4ada765a",
   "metadata": {},
   "source": [
    "# Conversation"
   ]
  },
  {
   "cell_type": "markdown",
   "id": "6b1edcc1",
   "metadata": {},
   "source": [
    "**Assistant**\n",
    "\n",
    "[Bug] TheFuck crashes when used\n",
    "\n",
    "<!-- If you have any issue with The Fuck, sorry about that, but we will do what we\r\n",
    "can to fix that. Actually, maybe we already have, so first thing to do is to\r\n",
    "update The Fuck and see if the bug is still there. \r\n",
    "\r\n",
    "(I'll play along) It was the newest in the first place\r\n",
    "-->\r\n",
    "\r\n",
    "<!-- If it is (sorry again), check if the problem has not already been reported and\r\n",
    "if not, just open an issue on [GitHub](https://github.com/nvbn/thefuck) with\r\n",
    "the following basic information: \r\n",
    "-->\r\n",
    "\r\n",
    "The output of `thefuck --version` :\r\n",
    "\r\n",
    "    The Fuck 3.25 using Python 3.6.4\r\n",
    "\r\n",
    "Shell:\r\n",
    "\r\n",
    "    Git Bash -> git version 2.15.1.windows.2\r\n",
    "\r\n",
    "Your system (Debian 7, ArchLinux, Windows, etc.):\r\n",
    "\r\n",
    "Windows 10\r\n",
    "\r\n",
    "How to reproduce the bug:\r\n",
    "\r\n",
    "    pip install thefuck\r\n",
    "\r\n",
    "configure .bashrc with `eval $(thefuck --alias)`\r\n",
    "\r\n",
    "Test it:\r\n",
    "\r\n",
    "    $ hlp\r\n",
    "    bash: hlp: command not found \r\n",
    "    $ fuck\r\n",
    "    [stacktrace]\r\n",
    "\r\n",
    "With THEFUCK_DEBUG set to true, the debug output and stacktrace:\r\n",
    "\r\n",
    "```\r\n",
    "DEBUG: Run with settings: {'alter_history': True,\r\n",
    " 'debug': True,\r\n",
    " 'env': {'GIT_TRACE': '1', 'LANG': 'C', 'LC_ALL': 'C'},\r\n",
    " 'exclude_rules': [],\r\n",
    " 'history_limit': None,\r\n",
    " 'instant_mode': False,\r\n",
    " 'no_colors': False,\r\n",
    " 'priority': {},\r\n",
    " 'repeat': False,\r\n",
    " 'require_confirmation': True,\r\n",
    " 'rules': [<const: All rules enabled>],\r\n",
    " 'slow_commands': ['lein', 'react-native', 'gradle', './gradlew', 'vagrant'],\r\n",
    " 'user_dir': WindowsPath('C:/Users/LunarWatcher/.config/thefuck'),\r\n",
    " 'wait_command': 3,\r\n",
    " 'wait_slow_command': 15}\r\n",
    "DEBUG: Received output: 'hlp' is not recognized as an internal or external command,\r\n",
    "operable program or batch file.\r\n",
    "\r\n",
    "DEBUG: Total took: 0:00:00.031233\r\n",
    "Traceback (most recent call last):\r\n",
    "  File \"c:\\users\\lunarwatcher\\appdata\\local\\programs\\python\\python36\\lib\\runpy.py\", line 193, in _run_module_as_main\r\n",
    "    \"__main__\", mod_spec)\r\n",
    "  File \"c:\\users\\lunarwatcher\\appdata\\local\\programs\\python\\python36\\lib\\runpy.py\", line 85, in _run_code\r\n",
    "    exec(code, run_globals)\r\n",
    "  File \"C:\\Users\\LunarWatcher\\AppData\\Local\\Programs\\Python\\Python36\\Scripts\\thefuck.exe\\__main__.py\", line 9, in <module>\r\n",
    "  File \"c:\\users\\lunarwatcher\\appdata\\local\\programs\\python\\python36\\lib\\site-packages\\thefuck\\entrypoints\\main.py\", line 25, in main\r\n",
    "    fix_command(known_args)\r\n",
    "  File \"c:\\users\\lunarwatcher\\appdata\\local\\programs\\python\\python36\\lib\\site-packages\\thefuck\\entrypoints\\fix_command.py\", line 41, in fix_command\r\n",
    "    corrected_commands = get_corrected_commands(command)\r\n",
    "  File \"c:\\users\\lunarwatcher\\appdata\\local\\programs\\python\\python36\\lib\\site-packages\\thefuck\\corrector.py\", line 89, in get_corrected_commands\r\n",
    "    corrected for rule in get_rules()\r\n",
    "  File \"c:\\users\\lunarwatcher\\appdata\\local\\programs\\python\\python36\\lib\\site-packages\\thefuck\\corrector.py\", line 46, in get_rules\r\n",
    "    paths = [rule_path for path in get_rules_import_paths()\r\n",
    "  File \"c:\\users\\lunarwatcher\\appdata\\local\\programs\\python\\python36\\lib\\site-packages\\thefuck\\corrector.py\", line 46, in <listcomp>\r\n",
    "    paths = [rule_path for path in get_rules_import_paths()\r\n",
    "  File \"c:\\users\\lunarwatcher\\appdata\\local\\programs\\python\\python36\\lib\\site-packages\\thefuck\\corrector.py\", line 34, in get_rules_import_paths\r\n",
    "    for contrib_module in Path(path).glob('thefuck_contrib_*'):\r\n",
    "  File \"c:\\users\\lunarwatcher\\appdata\\local\\programs\\python\\python36\\lib\\pathlib.py\", line 1078, in glob\r\n",
    "    for p in selector.select_from(self):\r\n",
    "  File \"c:\\users\\lunarwatcher\\appdata\\local\\programs\\python\\python36\\lib\\pathlib.py\", line 487, in select_from\r\n",
    "    if not is_dir(parent_path):\r\n",
    "  File \"c:\\users\\lunarwatcher\\appdata\\local\\programs\\python\\python36\\lib\\pathlib.py\", line 1326, in is_dir\r\n",
    "    return S_ISDIR(self.stat().st_mode)\r\n",
    "  File \"c:\\users\\lunarwatcher\\appdata\\local\\programs\\python\\python36\\lib\\pathlib.py\", line 1136, in stat\r\n",
    "    return self._accessor.stat(self)\r\n",
    "  File \"c:\\users\\lunarwatcher\\appdata\\local\\programs\\python\\python36\\lib\\pathlib.py\", line 387, in wrapped\r\n",
    "    return strfunc(str(pathobj), *args)\r\n",
    "OSError: [WinError 123] Filnavnet, mappenavnet eller volumnavnesyntaksen er feil: 'C:\\\\Program Files\\\\Git\\\\:' <---- This last part (roughly) translates to \"The filename, folder name or volume label syntax is wrong:\"\r\n",
    "```\r\n",
    "And this is fresh out of the box. I haven't used it before, and the crash happens right after installing. Re-installing doesn't do any good either. I can't install `python-dev`, because it's [not available for windows](https://stackoverflow.com/questions/16448710/how-to-get-python-dev-for-windows). And the pre-compiled binaries as posted in one of the answers doesn't have `python-dev` any more.\r\n",
    "\r\n",
    "I updated python too, to see if that made any difference, but it still crashes like that.\n"
   ]
  }
 ],
 "metadata": {},
 "nbformat": 4,
 "nbformat_minor": 5
}
