{
 "cells": [
  {
   "cell_type": "markdown",
   "id": "45e0ddc4",
   "metadata": {},
   "source": [
    "# Metadata\n",
    "\n",
    "**Python Topics** - debugging_and_tracing\n",
    "\n",
    "**Type** - query\n",
    "\n",
    "**Target Number of Turns (User + Assistant)** - 1\n"
   ]
  },
  {
   "cell_type": "markdown",
   "id": "df7eeaf4",
   "metadata": {},
   "source": [
    "# Conversation"
   ]
  },
  {
   "cell_type": "markdown",
   "id": "2f96c1b1",
   "metadata": {},
   "source": [
    "**User**\n",
    "\n",
    "Problem using \"fuck\" command on GCP while using Fish shell\n",
    "\n",
    "<!-- If you have any issue with The Fuck, sorry about that, but we will do what we\r\n",
    "can to fix that. Actually, maybe we already have, so first thing to do is to\r\n",
    "update The Fuck and see if the bug is still there. -->\r\n",
    "\r\n",
    "<!-- If it is (sorry again), check if the problem has not already been reported and\r\n",
    "if not, just open an issue on [GitHub](https://github.com/nvbn/thefuck) with\r\n",
    "the following basic information: -->\r\n",
    "\r\n",
    "**The output of `thefuck --version` (something like `The Fuck 3.1 using Python3.5.0 and Bash 4.4.12(1)-release`):**\r\n",
    "\r\n",
    "The Fuck 3.28 using Python 3.6.7 and Fish Shell 2.7.1\r\n",
    "\r\n",
    "**Your system (Debian 7, ArchLinux, Windows, etc.):**\r\n",
    "Output of Neofetch. I didn't change the shell fully to fish, I only attempted to run it as seen in the log entry below.\r\n",
    "\r\n",
    "OS: Ubuntu 18.04.2 LTS x86_64                                                              \r\n",
    "Host: Google Compute Engine                                                                \r\n",
    "Kernel: 4.15.0-1029-gcp                                                                    \r\n",
    "Uptime: 14 days, 18 hours, 26 mins                                                         \r\n",
    "Packages: 906                                                                              \r\n",
    "Shell: bash 4.4.19                                                                         \r\n",
    "Terminal: /dev/pts/0                                                                       \r\n",
    "CPU: Intel Xeon (1) @ 2.300GHz                                                             \r\n",
    "Memory: 1009MiB / 3693MiB \r\n",
    "\r\n",
    "**How to reproduce the bug:**\r\n",
    "With Fish installed, just type the commands as I have below in the debug output.\r\n",
    "\r\n",
    "**The output of The Fuck with `THEFUCK_DEBUG=true` exported (typically execute `export THEFUCK_DEBUG=true` in your shell before The Fuck):**\r\n",
    "\r\n",
    "\r\n",
    "```bash\r\n",
    "user@server ~> fish\r\n",
    "Welcome to fish, the friendly interactive shell\r\n",
    "user@server  ~> fuck\r\n",
    "No fucks given\r\n",
    "user@server ~> fuck\r\n",
    "Traceback (most recent call last):\r\n",
    "  File \"/usr/local/lib/python3.6/dist-packages/thefuck/output_readers/rerun.py\", line 36, in _wait_output\r\n",
    "    else settings.wait_command)\r\n",
    "  File \"/usr/local/lib/python3.6/dist-packages/psutil/__init__.py\", line 1380, in wait\r\n",
    "    return self._proc.wait(timeout)\r\n",
    "  File \"/usr/local/lib/python3.6/dist-packages/psutil/_pslinux.py\", line 1514, in wrapper\r\n",
    "    return fun(self, *args, **kwargs)\r\n",
    "  File \"/usr/local/lib/python3.6/dist-packages/psutil/_pslinux.py\", line 1720, in wait\r\n",
    "    return _psposix.wait_pid(self.pid, timeout, self._name)\r\n",
    "  File \"/usr/local/lib/python3.6/dist-packages/psutil/_psposix.py\", line 108, in wait_pid\r\n",
    "    delay = check_timeout(delay)\r\n",
    "  File \"/usr/local/lib/python3.6/dist-packages/psutil/_psposix.py\", line 70, in check_timeout\r\n",
    "    raise TimeoutExpired(timeout, pid=pid, name=proc_name)\r\n",
    "DEBUG: Total took: 0:00:03.486597\r\n",
    "Traceback (most recent call last):\r\n",
    "  File \"/usr/local/lib/python3.6/dist-packages/thefuck/output_readers/rerun.py\", line 36, in _wait_output\r\n",
    "    else settings.wait_command)\r\n",
    "  File \"/usr/local/lib/python3.6/dist-packages/psutil/__init__.py\", line 1380, in wait\r\n",
    "    return self._proc.wait(timeout)\r\n",
    "  File \"/usr/local/lib/python3.6/dist-packages/psutil/_pslinux.py\", line 1514, in wrapper\r\n",
    "    return fun(self, *args, **kwargs)\r\n",
    "  File \"/usr/local/lib/python3.6/dist-packages/psutil/_pslinux.py\", line 1720, in wait\r\n",
    "    return _psposix.wait_pid(self.pid, timeout, self._name)\r\n",
    "  File \"/usr/local/lib/python3.6/dist-packages/psutil/_psposix.py\", line 108, in wait_pid\r\n",
    "    delay = check_timeout(delay)\r\n",
    "  File \"/usr/local/lib/python3.6/dist-packages/psutil/_psposix.py\", line 70, in check_timeout\r\n",
    "    raise TimeoutExpired(timeout, pid=pid, name=proc_name)\r\n",
    "psutil.TimeoutExpired: psutil.TimeoutExpired timeout after 3 seconds (pid=22101)\r\n",
    "During handling of the above exception, another exception occurred:\r\n",
    "Traceback (most recent call last):\r\n",
    "  File \"/usr/local/bin/thefuck\", line 10, in <module>\r\n",
    "    sys.exit(main())\r\n",
    "  File \"/usr/local/lib/python3.6/dist-packages/thefuck/entrypoints/main.py\", line 26, in main\r\n",
    "    fix_command(known_args)\r\n",
    "  File \"/usr/local/lib/python3.6/dist-packages/thefuck/entrypoints/fix_command.py\", line 36, in fix_command\r\n",
    "    command = types.Command.from_raw_script(raw_command)\r\n",
    "  File \"/usr/local/lib/python3.6/dist-packages/thefuck/types.py\", line 82, in from_raw_script\r\n",
    "    output = get_output(script, expanded)\r\n",
    "  File \"/usr/local/lib/python3.6/dist-packages/thefuck/output_readers/__init__.py\", line 20, in get_output\r\n",
    "    return rerun.get_output(script, expanded)\r\n",
    "  File \"/usr/local/lib/python3.6/dist-packages/thefuck/output_readers/rerun.py\", line 61, in get_output\r\n",
    "    if _wait_output(result, is_slow):\r\n",
    "  File \"/usr/local/lib/python3.6/dist-packages/thefuck/output_readers/rerun.py\", line 40, in _wait_output\r\n",
    "    _kill_process(child)\r\n",
    "  File \"/usr/local/lib/python3.6/dist-packages/thefuck/output_readers/rerun.py\", line 17, in _kill_process\r\n",
    "    proc.kill()\r\n",
    "  File \"/usr/local/lib/python3.6/dist-packages/psutil/__init__.py\", line 387, in wrapper\r\n",
    "    raise NoSuchProcess(self.pid, self._name)\r\n",
    "psutil.NoSuchProcess: psutil.NoSuchProcess process no longer exists (pid=22110)\r\n",
    "user@server  ~> \r\n",
    "```\r\n",
    "<!-- It's only with enough information that we can do something to fix the problem. -->\r\n",
    "\n"
   ]
  }
 ],
 "metadata": {},
 "nbformat": 4,
 "nbformat_minor": 5
}
