{
 "cells": [
  {
   "cell_type": "markdown",
   "id": "55709373",
   "metadata": {},
   "source": [
    "# Metadata\n",
    "\n",
    "**Python Topics** - debugging_and_tracing\n",
    "\n",
    "**Type** - query\n",
    "\n",
    "**Target Number of Turns (User + Assistant)** - 3\n"
   ]
  },
  {
   "cell_type": "markdown",
   "id": "f26751ae",
   "metadata": {},
   "source": [
    "# Conversation"
   ]
  },
  {
   "cell_type": "markdown",
   "id": "05fb5f54",
   "metadata": {},
   "source": [
    "**Assistant**\n",
    "\n",
    "Exception in python3 + fish\n",
    "\n",
    "Version: The Fuck 3.23 using Python 3.5.2\r\n",
    "OS: Ubuntu 16.04 Gnome\r\n",
    "Shell: fish, version 2.2.0\r\n",
    "\r\n",
    "The command works fine in bash, no errors. The python 2 version also works fine in both bash and fish.\r\n",
    "When I execute the python 3 version in fish, I get the error below. Any ideas how to fix this?\r\n",
    "\r\n",
    "```\r\n",
    "DEBUG: Run with settings: {'alter_history': True,\r\n",
    " 'debug': True,\r\n",
    " 'env': {'GIT_TRACE': '1', 'LANG': 'C', 'LC_ALL': 'C'},\r\n",
    " 'exclude_rules': [],\r\n",
    " 'history_limit': None,\r\n",
    " 'instant_mode': False,\r\n",
    " 'no_colors': False,\r\n",
    " 'priority': {},\r\n",
    " 'repeat': False,\r\n",
    " 'require_confirmation': True,\r\n",
    " 'rules': [<const: All rules enabled>],\r\n",
    " 'slow_commands': ['lein', 'react-native', 'gradle', './gradlew', 'vagrant'],\r\n",
    " 'user_dir': PosixPath('/home/robert/.config/thefuck'),\r\n",
    " 'wait_command': 3,\r\n",
    " 'wait_slow_command': 15}\r\n",
    "DEBUG: Total took: 0:00:00.001479\r\n",
    "Traceback (most recent call last):\r\n",
    "  File \"/usr/local/lib/python3.5/dist-packages/thefuck/utils.py\", line 231, in _cache\r\n",
    "    with closing(shelve.open(cache_path)) as db:\r\n",
    "  File \"/usr/lib/python3.5/shelve.py\", line 243, in open\r\n",
    "    return DbfilenameShelf(filename, flag, protocol, writeback)\r\n",
    "  File \"/usr/lib/python3.5/shelve.py\", line 227, in __init__\r\n",
    "    Shelf.__init__(self, dbm.open(filename, flag), protocol, writeback)\r\n",
    "  File \"/usr/lib/python3.5/dbm/__init__.py\", line 88, in open\r\n",
    "    raise error[0](\"db type could not be determined\")\r\n",
    "dbm.error: db type could not be determined\r\n",
    "\r\n",
    "During handling of the above exception, another exception occurred:\r\n",
    "\r\n",
    "Traceback (most recent call last):\r\n",
    "  File \"/usr/local/bin/thefuck\", line 11, in <module>\r\n",
    "    sys.exit(main())\r\n",
    "  File \"/usr/local/lib/python3.5/dist-packages/thefuck/main.py\", line 53, in main\r\n",
    "    fix_command(known_args)\r\n",
    "  File \"/usr/local/lib/python3.5/dist-packages/thefuck/main.py\", line 29, in fix_command\r\n",
    "    command = types.Command.from_raw_script(raw_command)\r\n",
    "  File \"/usr/local/lib/python3.5/dist-packages/thefuck/types.py\", line 75, in from_raw_script\r\n",
    "    expanded = shell.from_shell(script)\r\n",
    "  File \"/usr/local/lib/python3.5/dist-packages/thefuck/shells/generic.py\", line 30, in from_shell\r\n",
    "    return self._expand_aliases(command_script)\r\n",
    "  File \"/usr/local/lib/python3.5/dist-packages/thefuck/shells/fish.py\", line 47, in _expand_aliases\r\n",
    "    aliases = self.get_aliases()\r\n",
    "  File \"/usr/local/lib/python3.5/dist-packages/thefuck/utils.py\", line 33, in wrapper\r\n",
    "    memo[key] = fn(*args, **kwargs)\r\n",
    "  File \"<decorator-gen-4>\", line 2, in get_aliases\r\n",
    "  File \"/usr/local/lib/python3.5/dist-packages/thefuck/utils.py\", line 238, in _cache\r\n",
    "    except (shelve_open_error, ImportError):\r\n",
    "TypeError: catching classes that do not inherit from BaseException is not allowed\r\n",
    "```\r\n",
    "\n"
   ]
  }
 ],
 "metadata": {},
 "nbformat": 4,
 "nbformat_minor": 5
}
